Workbook

Sheet Leia-me
A1: MAPA DE SERVIÇOS, MARCAS, HUBS E ARQUITETURA DO SITE
A2: Empresa | B2: Vaff Engenharia
A3: Objetivo | B3: Reunir todos os serviços, termos relacionados, marcas, companhias e sistemas construtivos, com intenção de busca, tipo de página, URL e posição na arquitetura do site, para a Vaff Engenharia decidir o que publicar.
A5: ABAS
A6: Arquitetura | B6: Árvore completa do site: páginas institucionais, de conversão, de perfil, hubs de serviço, hub de marcas e regras de URL e links internos.
A7: Menu | B7: Menu principal, mega menu de serviços, mega menu de marcas e sistemas, menu mobile e rodapé.
A8: Tipos de Página | B8: Catálogo de todos os tipos de página usados nas outras abas: para que servem, blocos obrigatórios, CTA, dados estruturados, regra de publicação e quantas páginas de cada tipo existem.
A9: Hubs | B9: Resumo dos 12 hubs de serviço e do hub Marcas e Sistemas, com contagens automáticas a partir dos dois mapas.
A10: Mapa de Serviços | B10: Uma palavra por linha: pilares, subhubs, serviços, conteúdos e normas técnicas, com intenção, página, URL e prioridade.
A11: Mapa de Marcas | B11: Uma palavra por linha ligada a marca, companhia ou sistema construtivo: fabricantes, equipamentos, seguradoras, bancos, construtoras, concessionárias, órgãos públicos, entidades, plataformas e sistemas.
A12: Padrões de Marca | B12: Os modelos de palavra-chave usados para gerar o Mapa de Marcas, por categoria, com serviço âncora, tipo de página e regra de publicação. Serve para incluir novas marcas no futuro.
A13: Camadas Programáticas | B13: Resumo das camadas de páginas geradas por combinação, como serviço por cidade, marca por serviço e seguradora por sinistro, seguido da tabela de combinações de serviço por cidade e por bairro.
A14: Marcas | B14: Uma linha por marca ou operadora, com a primeira coluna sendo o nome da marca: hubs onde atua, categoria, exemplos de busca navegacional e comparativa, intenção, tipo de página, URL e nível na arquitetura.
A16: COMO PREENCHER
A17: Células amarelas | B17: As colunas Decisão Vaff e Observação são as únicas para preencher. Decisão aceita: Aprovar, Talvez ou Descartar.
A18: Exemplo de preenchimento | B18: Palavra: Laudo de rachaduras | Decisão Vaff: Aprovar | Observação: Já fazemos, definir preço a partir de com o Vlad.
A19: Filtros | B19: Todas as tabelas têm filtro no cabeçalho. Sugestão: filtrar por Hub e Prioridade sugerida e fazer a triagem por partes.
A21: LEGENDA DAS COLUNAS
A22: Intenção de busca | B22: Informacional: quer aprender. Comercial: está comparando antes de contratar. Transacional: quer contratar ou resolver agora. Navegacional: procura uma empresa, órgão ou marca específica.
A23: Estágio do funil | B23: Topo para informacional, Meio para comercial, Fundo para transacional e navegacional.
A24: Intenção por trás da busca | B24: O que a pessoa realmente quer resolver, o medo ou a pressão que a fez buscar. Base para o texto da página.
A25: Tipo de página | B25: Ver a aba Tipos de Página.
A26: Consolidar em | B26: Quando preenchida, o termo é sinônimo de outra página e vira seção dela, evitando que duas páginas disputem a mesma busca.
A27: Aderência sugerida | B27: Core: a Vaff já entrega. Adjacente: próximo do que entrega. Parceiro: entregar com parceiros. Fora: baixa aderência. Sugestão baseada na reunião de 21/09; a Vaff confirma na coluna Decisão.
A28: Prioridade sugerida | B28: Alta, Média ou Baixa, cruzando aderência, ICP e potencial de conversão. Não é volume de busca.
A29: Concorrência local | B29: Lacuna, em verde: não aparece nos sites dos concorrentes da Grande Florianópolis analisados em 24/09/2026, como UNA, Plage, Resulta, EnGiô, Case, Realiza, Clara, Reforma.com, Renovar, Deutsch, QCR, F5 e Tohrú. Comum: oferecido por vários deles. Não verificado: fora da amostra. Revisar a cada seis meses.
A31: CUIDADOS
A32: Marcas de terceiros | B32: Nas páginas com marcas, não sugerir parceria, credenciamento ou vínculo que não exista e não usar logotipos. Validar textos com o jurídico.
A33: Páginas programáticas | B33: Só publicar página local ou de marca com conteúdo único: obras reais, particularidades do local, especificação técnica. Página copiada com troca de nome é descartada pelo Google.
A34: Volume de busca | B34: Volumes e dificuldade devem ser levantados pela Turma Turbo antes de definir a ordem de produção.
A35: Google Meu Negócio | B35: A lista de serviços aprovada deve ser a mesma cadastrada no perfil do Google.

Sheet Arquitetura
A1: Nível | B1: Seção do site | C1: Página | D1: URL | E1: Tipo de página | F1: Objetivo da página | G1: Persona principal | H1: CTA principal | I1: Links internos obrigatórios
A2: 0 | B2: Home | C2: Página inicial | D2: / | E2: Home | F2: Posicionar a Vaff como engenharia de alto padrão livre de dor de cabeça, filtrar o público e distribuir para hubs, perfis e obras. | G2: Patrimonialista Ocupado, Síndico Profissional, Dono que Não Pode Parar | H2: Solicitar proposta | I2: Hubs principais, páginas de perfil, obras em destaque, depoimentos, sobre
A3: 1 | B3: Serviços | C3: Todos os serviços | D3: /servicos/ | E3: Índice de serviços | F3: Mostrar a amplitude da Vaff com os 12 hubs e os serviços mais procurados. | G3: Todos | H3: Solicitar proposta | I3: Todos os hubs
A4: 2 | B4: Serviços | C4: Construção | D4: /construcao/ | E4: Página pilar | F4: Ranquear para construtora de alto padrão em florianópolis e distribuir para subhubs e serviços. Execução de casas, edifícios e obras comerciais do zero, incluindo sistemas construtivos, fundações e áreas externas. | G4: Patrimonialista Ocupado, Recém-Chegado, Construtor por Paixão, Dono que Não Pode Parar, Incorporador Enxuto | H4: Solicitar proposta | I4: Subhubs do hub, 3 obras do tipo, artigos do hub, página de perfil relacionada
A5: 3 | B5: Serviços | C5: Construção de casas de alto padrão | D5: /construcao/construcao-casas-alto-padrao/ | E5: Página de subhub | F5: Quer construir a casa e está escolhendo em quem confiar. Pesquisa portfólio, processo, prazo e faixa de investimento antes de pedir proposta; o medo central é a obra sem fim e o orçamento que estoura. | G5: Patrimonialista Ocupado, Recém-Chegado, Construtor por Paixão | H5: Solicitar proposta | I5: Serviços do subhub, pilar do hub, conteúdos relacionados
A6: 3 | B6: Serviços | C6: Sistemas construtivos | D6: /construcao/sistemas-construtivos/ | E6: Página de subhub | F6: Já ouviu falar de um sistema construtivo e quer saber se vale a pena, quanto custa e quem executa com segurança. Está em fase de comparação técnica, aberto a ser educado. | G6: Recém-Chegado, Construtor por Paixão, Incorporador Enxuto | H6: Solicitar proposta | I6: Serviços do subhub, pilar do hub, conteúdos relacionados
A7: 3 | B7: Serviços | C7: Ambientes e anexos residenciais | D7: /construcao/ambientes-e-anexos-residenciais/ | E7: Página de subhub | F7: Quer acrescentar um espaço de lazer ou uso específico à casa existente. Busca execução caprichada sem transtornar a rotina da família. | G7: Patrimonialista Ocupado, Construtor por Paixão | H7: Solicitar proposta | I7: Serviços do subhub, pilar do hub, conteúdos relacionados
A8: 3 | B8: Serviços | C8: Edifícios residenciais | D8: /construcao/edificios-residenciais/ | E8: Página de subhub | F8: Investidor ou incorporador sem engenharia interna procurando quem execute ou gerencie um empreendimento. Avalia solidez, histórico e capacidade de cumprir cronograma. | G8: Incorporador Enxuto | H8: Solicitar proposta | I8: Serviços do subhub, pilar do hub, conteúdos relacionados
A9: 3 | B9: Serviços | C9: Obras comerciais e corporativas | D9: /construcao/obras-comerciais-e-corporativas/ | E9: Página de subhub | F9: Dono de negócio ou gestor que precisa do espaço pronto na data certa. Procura experiência comprovada no mesmo tipo de obra e segurança nas aprovações. | G9: Dono que Não Pode Parar, Empresa que Chega, Incorporador Enxuto | H9: Solicitar proposta | I9: Serviços do subhub, pilar do hub, conteúdos relacionados
A10: 3 | B10: Serviços | C10: Obras de saúde | D10: /construcao/obras-saude/ | E10: Página de subhub | F10: Profissional de saúde que vai abrir ou ampliar o espaço. Tem medo de reprovação na Vigilância Sanitária e de atrasar a agenda de pacientes. | G10: Dono que Não Pode Parar | H10: Solicitar proposta | I10: Serviços do subhub, pilar do hub, conteúdos relacionados
A11: 3 | B11: Serviços | C11: Obras educacionais e institucionais | D11: /construcao/obras-educacionais-e-institucionais/ | E11: Página de subhub | F11: Mantenedora, diretoria ou entidade que precisa de obra defensável perante conselho e associados, com documentação impecável e prazo alinhado ao calendário. | G11: Instituição, Dono que Não Pode Parar | H11: Solicitar proposta | I11: Serviços do subhub, pilar do hub, conteúdos relacionados
A12: 3 | B12: Serviços | C12: Hotelaria e turismo | D12: /construcao/hotelaria-e-turismo/ | E12: Página de subhub | F12: Empreendedor de hospedagem que precisa construir ou ampliar fora da temporada, com acabamento que resista ao uso intenso e gere boas avaliações. | G12: Dono de Pousada, Investidor de Renda | H12: Solicitar proposta | I12: Serviços do subhub, pilar do hub, conteúdos relacionados
A13: 3 | B13: Serviços | C13: Galpões e obras industriais | D13: /construcao/galpoes-e-obras-industriais/ | E13: Página de subhub | F13: Empresa ou investidor que precisa de galpão funcional, rápido e com custo previsível; compara sistemas e prazos. | G13: Dono que Não Pode Parar, Incorporador Enxuto | H13: Solicitar proposta | I13: Serviços do subhub, pilar do hub, conteúdos relacionados
... A220: 2 | B220: Contato | C220: Formulário de consultoria | D220: /solicitar-proposta/consultoria/ | E220: Formulário qualificado | F220: Campos obrigatórios que qualificam e evitam idas e vindas no WhatsApp. | G220: Todos | H220: Enviar | I220: Página de obrigado com próximo passo
A221: 1 | B221: Institucional | C221: Política de privacidade | D221: /politica-de-privacidade/ | E221: Legal | F221: Adequação à LGPD, necessária por causa dos formulários. | G221: Todos
A223: REGRAS DE ARQUITETURA
A224: URLs curtas, em minúsculas, sem acento e com hífen. Serviços ficam sob o hub: /hub/servico/. Páginas locais e de marca ficam sob o serviço: /hub/servico/local/.
A225: Subhubs aparecem no breadcrumb e nos links internos, mas não entram na URL do serviço, para manter URLs curtas e estáveis se a organização mudar.
A226: Breadcrumb em todas as páginas: Início > Hub > Subhub > Serviço.
A227: Cada página de serviço linka para o subhub, para o pilar do hub, para dois serviços relacionados, dois artigos e uma obra do mesmo tipo.
A228: Cada artigo linka para a página de serviço que resolve a dúvida. Conteúdo sempre empurra para o fundo do funil.
A229: Termos com a coluna Consolidar em preenchida viram seções e perguntas frequentes da página canônica, não páginas novas.
A230: Dados estruturados sugeridos: Organization, LocalBusiness, Service, FAQPage, BreadcrumbList e Review.
A231: Cada serviço publicado deve existir com o mesmo nome no Google Meu Negócio.
A232: Nenhuma página órfã: toda página nova precisa receber ao menos um link do seu hub e de uma página de conteúdo.

Sheet Menu
A1: Área | B1: Posição | C1: Item de menu | D1: URL | E1: Itens em destaque | F1: Observação
A2: Menu principal | B2: 1 | C2: Serviços | D2: /servicos/ | E2: Mega menu com os 12 hubs de serviço em colunas | F2: Item mais importante; abre o mega menu. No rodapé de cada coluna, link Por marca para as categorias ligadas ao hub.
A3: Menu principal | B3: 2 | C3: Marcas e Sistemas | D3: /marcas-e-sistemas/ | E3: Mega menu com materiais, acabamentos, proteção e cobertura, equipamentos e sistemas construtivos | F3: Entrada para quem chega pelo nome do fabricante, do equipamento ou do sistema.
A4: Menu principal | B4: 3 | C4: Para você | D4: /para-voce/ | E4: Proprietários, Síndicos, Empresas, Incorporadores, Arquitetos, Advogados, Corretores, Quem mora fora | F4: Atalho por persona, reduz o esforço de quem não sabe o nome do serviço.
A5: Menu principal | B5: 4 | C5: Obras | D5: /obras/ | E5: Residenciais, Comerciais, Saúde, Educação, Condomínios, Edifícios, Galpões, Premiadas | F5: Prova é o principal argumento de venda.
A6: Menu principal | B6: 5 | C6: Sobre | D6: /sobre/ | E6: Equipe, Como trabalhamos, Reconhecimentos, Depoimentos, Garantia
A7: Menu principal | B7: 6 | C7: Conteúdo | D7: /blog/ | E7: Blog, Guias, Ferramentas, Perguntas frequentes
A8: Menu principal | B8: 7 | C8: Contato | D8: /contato/
A9: Menu principal | B9: 8 | C9: Solicitar proposta | D9: /solicitar-proposta/ | F9: Botão destacado, fixo no topo.
A10: Mega menu Serviços | C10: Construção | D10: /construcao/ | E10: Construção de casa de alto padrão, Construção de casa em condomínio fechado, Construção de casa de praia, Construção de casa de campo, Construção de casa térrea, Construção de sobrado | F10: Coluna do hub com link Ver todos para a página pilar. Link Por marca: Aço para construção, Piscinas.
A11: Mega menu Serviços | C11: Reformas | D11: /reformas/ | E11: Reforma de casa, Reforma de apartamento de alto padrão, Reforma de escritório, Reforma de clínica, Reforma residencial, Reforma de apartamento | F11: Coluna do hub com link Ver todos para a página pilar. Link Por marca: Revestimentos cerâmicos, Metais e louças, Argamassas e rejuntes, Tintas, Drywall e forros, Telhas e coberturas, Pisos de madeira e vinílicos, Superfícies e pedras, Vidros, Painéis de madeira, Piscinas.
A12: Mega menu Serviços | C12: Projetos de Engenharia | D12: /projetos/ | E12: Projeto estrutural, Projeto elétrico, Projeto de entrada de energia, Projeto hidrossanitário, Projeto preventivo contra incêndio, Orçamento de obra | F12: Coluna do hub com link Ver todos para a página pilar. Link Por marca: Tubos e conexões, Cimento e concreto, Aço para construção, Impermeabilizantes, Elevadores, Climatização, Aquecimento a gás, Geradores, Automação, Segurança eletrônica.
A13: Mega menu Serviços | C13: Laudos Técnicos | D13: /laudos-tecnicos/ | E13: Laudo estrutural, Laudo de rachaduras, Laudo de infiltração, Laudo de vícios construtivos, Laudo de sinistro, Laudo de danos por vendaval | F13: Coluna do hub com link Ver todos para a página pilar. Link Por marca: Tubos e conexões, Aço para construção, Revestimentos cerâmicos, Metais e louças, Argamassas e rejuntes, Impermeabilizantes, Tintas, Telhas e coberturas, Pisos de madeira e vinílicos, Energia solar.
A14: Mega menu Serviços | C14: Vistorias e Inspeções | D14: /vistorias-e-inspecoes/ | E14: Vistoria de entrega de apartamento, Vistoria de imóvel antes da compra, Vistoria cautelar, Inspeção predial, Vistoria de entrega de casa, Assistência técnica em recebimento de condomínio novo | F14: Coluna do hub com link Ver todos para a página pilar. Link Por marca: Cimento e concreto.
A15: Mega menu Serviços | C15: Perícias e Avaliações | D15: /pericias-e-avaliacoes/ | E15: Parecer técnico para ação contra construtora, Avaliação de imóvel de alto padrão, Estimativa de custo de reforma para compra de imóvel, Perícia judicial, Perícia extrajudicial, Assistência técnica em perícia judicial | F15: Coluna do hub com link Ver todos para a página pilar.
A16: Mega menu Serviços | C16: Gestão e Fiscalização de Obras | D16: /gestao-de-obras/ | E16: Gestão de obras residenciais, Gestão de obra à distância, Gestão de obra para estrangeiros, Gestão de obra de casa de veraneio, Administração de obras, Retomada de obra paralisada | F16: Coluna do hub com link Ver todos para a página pilar.
A17: Mega menu Serviços | C17: Condomínios | D17: /condominios/ | E17: Assessoria técnica para síndicos, Participação técnica em assembleia, Fiscalização de obras de condomínio, Fiscalização de reforma de fachada, Elaboração de memorial descritivo para cotação, Análise de planos de reforma de unidades | F17: Coluna do hub com link Ver todos para a página pilar.
A18: Mega menu Serviços | C18: Consultoria Técnica | D18: /consultoria/ | E18: Consultoria técnica online, Consultoria técnica internacional, Segunda opinião técnica sobre obra em andamento, Visita técnica, Revisão técnica de proposta de construtora, Consultoria técnica presencial | F18: Coluna do hub com link Ver todos para a página pilar.
A19: Mega menu Serviços | C19: Regularização e Aprovações | D19: /regularizacao/ | E19: Regularização de obra, Obtenção de habite-se, Averbação de construção, Aprovação no Corpo de Bombeiros, Regularização de construção sem projeto, Regularização de ampliação | F19: Coluna do hub com link Ver todos para a página pilar.
A20: Mega menu Serviços | C20: Recuperação e Manutenção | D20: /recuperacao-e-manutencao/ | E20: Impermeabilização, Reforma de fachada, Revisão pré-temporada de imóvel, Recuperação estrutural, Reforço estrutural, Reforço de fundação | F20: Coluna do hub com link Ver todos para a página pilar. Link Por marca: Cimento e concreto, Aço para construção, Revestimentos cerâmicos, Impermeabilizantes, Tintas, Telhas e coberturas, Superfícies e pedras, Vidros.
A21: Mega menu Serviços | C21: Instalações e Sistemas | D21: /instalacoes/ | E21: Instalação elétrica, Reforma de instalação elétrica, Troca de fiação, Adequação de quadro elétrico, Aumento de carga elétrica, Instalação de gerador | F21: Coluna do hub com link Ver todos para a página pilar. Link Por marca: Tubos e conexões, Elevadores, Climatização, Aquecimento a gás, Geradores, Energia solar, Automação, Segurança eletrônica, Material elétrico.
A22: Mega menu Marcas e Sistemas | C22: Materiais básicos e estruturais | E22: Tubos e conexões, Cimento e concreto, Aço para construção | F22: Título de coluna do mega menu.
A23: Mega menu Marcas e Sistemas | C23: Tubos e conexões | D23: /marcas-e-sistemas/tubos-e-conexoes/ | E23: Tigre, Amanco, Krona | F23: Subitem da coluna; cada marca leva à sua página.
A24: Mega menu Marcas e Sistemas | C24: Cimento e concreto | D24: /marcas-e-sistemas/cimento-e-concreto/ | E24: Votorantim, Itambé, InterCement, CSN Cimentos | F24: Subitem da coluna; cada marca leva à sua página.
A25: Mega menu Marcas e Sistemas | C25: Aço para construção | D25: /marcas-e-sistemas/aco-para-construcao/ | E25: Gerdau, ArcelorMittal, CSN | F25: Subitem da coluna; cada marca leva à sua página.
A26: Mega menu Marcas e Sistemas | C26: Acabamentos | E26: Revestimentos cerâmicos, Metais e louças, Argamassas e rejuntes, Tintas, Drywall e forros, Pisos de madeira e vinílicos, Superfícies e pedras, Vidros, Painéis de madeira | F26: Título de coluna do mega menu.
A27: Mega menu Marcas e Sistemas | C27: Revestimentos cerâmicos | D27: /marcas-e-sistemas/revestimentos-ceramicos/ | E27: Portobello, Eliane, Portinari, Decortiles, Incepa, Roca Cerâmica | F27: Subitem da coluna; cada marca leva à sua página.
A28: Mega menu Marcas e Sistemas | C28: Metais e louças | D28: /marcas-e-sistemas/metais-e-loucas/ | E28: Deca, Docol, Lorenzetti, Tramontina, Celite, Roca, Grohe, Hansgrohe, Kohler | F28: Subitem da coluna; cada marca leva à sua página.
A29: Mega menu Marcas e Sistemas | C29: Argamassas e rejuntes | D29: /marcas-e-sistemas/argamassas-e-rejuntes/ | E29: Quartzolit, Votomassa | F29: Subitem da coluna; cada marca leva à sua página.
A30: Mega menu Marcas e Sistemas | C30: Tintas | D30: /marcas-e-sistemas/tintas/ | E30: Suvinil, Coral, Sherwin-Williams, Lukscolor | F30: Subitem da coluna; cada marca leva à sua página.
A31: Mega menu Marcas e Sistemas | C31: Drywall e forros | D31: /marcas-e-sistemas/drywall-e-forros/ | E31: Placo, Knauf | F31: Subitem da coluna; cada marca leva à sua página.
A32: Mega menu Marcas e Sistemas | C32: Pisos de madeira e vinílicos | D32: /marcas-e-sistemas/pisos-madeira-e-vinilicos/ | E32: Durafloor, Eucafloor, Indusparquet, Tarkett, Quick-Step | F32: Subitem da coluna; cada marca leva à sua página.
A33: Mega menu Marcas e Sistemas | C33: Superfícies e pedras | D33: /marcas-e-sistemas/superficies-e-pedras/ | E33: Dekton, Silestone, Neolith | F33: Subitem da coluna; cada marca leva à sua página.
A34: Mega menu Marcas e Sistemas | C34: Vidros | D34: /marcas-e-sistemas/vidros/ | E34: Cebrace, Guardian, Saint-Gobain Glass | F34: Subitem da coluna; cada marca leva à sua página.
A35: Mega menu Marcas e Sistemas | C35: Painéis de madeira | D35: /marcas-e-sistemas/paineis-madeira/ | E35: Duratex, Arauco, Berneck | F35: Subitem da coluna; cada marca leva à sua página.
A36: Mega menu Marcas e Sistemas | C36: Proteção e cobertura | E36: Impermeabilizantes, Telhas e coberturas | F36: Título de coluna do mega menu.
A37: Mega menu Marcas e Sistemas | C37: Impermeabilizantes | D37: /marcas-e-sistemas/impermeabilizantes/ | E37: Viapol, Vedacit, Sika, Quartzolit, Denver Impermeabilizantes, MC-Bauchemie | F37: Subitem da coluna; cada marca leva à sua página.
A38: Mega menu Marcas e Sistemas | C38: Telhas e coberturas | D38: /marcas-e-sistemas/telhas-e-coberturas/ | E38: Brasilit, Eternit, Tégula, Owens Corning, IKO, Kingspan Isoeste | F38: Subitem da coluna; cada marca leva à sua página.
A39: Mega menu Marcas e Sistemas | C39: Equipamentos | E39: Elevadores, Climatização, Aquecimento a gás, Geradores, Energia solar, Automação, Segurança eletrônica, Material elétrico, Piscinas | F39: Título de coluna do mega menu.
A40: Mega menu Marcas e Sistemas | C40: Elevadores | D40: /marcas-e-sistemas/elevadores/ | E40: TK Elevator, Otis, Atlas Schindler, Daiken | F40: Subitem da coluna; cada marca leva à sua página.
...

Sheet Tipos de Página
A1: Tipo de página | B1: Família | C1: O que é | D1: Objetivo | E1: Intenção atendida | F1: Nível típico | G1: Padrão de URL | H1: Blocos obrigatórios | I1: CTA principal | J1: Dados estruturados | K1: Regra de publicação | L1: Qtde no Mapa de Serviços | M1: Qtde no Mapa de Marcas | N1: Qtde nas Camadas Programáticas | O1: Qtde na Arquitetura
A2: Home | B2: Institucional | C2: Página inicial do site. | D2: Posicionar a Vaff como engenharia de alto padrão livre de dor de cabeça e distribuir o visitante. | E2: Navegacional | F2: N0 | G2: / | H2: Proposta de valor, hubs, perfis, obras, depoimentos, triângulo preço prazo qualidade, pré-requisitos | I2: Solicitar proposta | J2: Organization, LocalBusiness | K2: Única. | L2: =COUNTIF('Mapa de Serviços'!$J:$J,$A2) -> 0 | M2: =COUNTIF('Mapa de Marcas'!$L:$L,$A2) -> 0 | N2: =COUNTIF('Camadas Programáticas'!$I$15:$I$272,$A2) -> 0 | O2: =COUNTIF(Arquitetura!$E:$E,$A2) -> 1
A3: Página pilar | B3: Serviços | C3: Página principal de cada hub. | D3: Ranquear o termo amplo do hub e distribuir para subhubs e serviços. | E3: Comercial | F3: N1 | G3: /hub/ | H3: Introdução, subhubs, serviços em destaque, obras do hub, perguntas frequentes, CTA | I3: Solicitar proposta | J3: Service, BreadcrumbList, FAQPage | K3: Uma por hub. | L3: =COUNTIF('Mapa de Serviços'!$J:$J,$A3) -> 12 | M3: =COUNTIF('Mapa de Marcas'!$L:$L,$A3) -> 1 | N3: =COUNTIF('Camadas Programáticas'!$I$15:$I$272,$A3) -> 0 | O3: =COUNTIF(Arquitetura!$E:$E,$A3) -> 13
A4: Página de subhub | B4: Serviços | C4: Agrupa serviços de uma mesma categoria dentro do hub. | D4: Atender quem sabe a categoria do problema mas não o serviço exato. | E4: Comercial | F4: N2 | G4: /hub/subhub/ | H4: Explicação da categoria, lista de serviços com resumo, obra, CTA | I4: Solicitar proposta | J4: BreadcrumbList, ItemList | K4: Uma por subhub aprovado. | L4: =COUNTIF('Mapa de Serviços'!$J:$J,$A4) -> 81 | M4: =COUNTIF('Mapa de Marcas'!$L:$L,$A4) -> 0 | N4: =COUNTIF('Camadas Programáticas'!$I$15:$I$272,$A4) -> 0 | O4: =COUNTIF(Arquitetura!$E:$E,$A4) -> 81
A5: Página de serviço | B5: Serviços | C5: Página de conversão de um serviço específico. | D5: Converter a busca do serviço. | E5: Transacional | F5: N3 | G5: /hub/servico/ | H5: Dor, solução, processo, prova, preço a partir de, perguntas frequentes, formulário qualificado | I5: Formulário do serviço | J5: Service, FAQPage, BreadcrumbList, Review | K5: Criar para cada serviço aprovado. | L5: =COUNTIF('Mapa de Serviços'!$J:$J,$A5) -> 680 | M5: =COUNTIF('Mapa de Marcas'!$L:$L,$A5) -> 0 | N5: =COUNTIF('Camadas Programáticas'!$I$15:$I$272,$A5) -> 0 | O5: =COUNTIF(Arquitetura!$E:$E,$A5) -> 12
A6: Seção dentro de outra página | B6: Serviços | C6: Sinônimo ou variação tratado como seção da página canônica. | D6: Capturar a variação sem canibalizar. | E6: Transacional | F6: Seção | G6: /hub/servico/#secao | H6: Subtítulo com o termo, parágrafo, pergunta frequente | I6: CTA da página | J6: Incluído no FAQPage | K6: Nunca criar URL própria. | L6: =COUNTIF('Mapa de Serviços'!$J:$J,$A6) -> 46 | M6: =COUNTIF('Mapa de Marcas'!$L:$L,$A6) -> 0 | N6: =COUNTIF('Camadas Programáticas'!$I$15:$I$272,$A6) -> 0 | O6: =COUNTIF(Arquitetura!$E:$E,$A6) -> 0
A7: Página de serviço principal | B7: Camadas programáticas | C7: A própria página do serviço otimizada para Florianópolis. | D7: Evitar página local duplicada para a praça principal. | E7: Transacional | F7: N3 | G7: /hub/servico/ | H7: Menção a bairros atendidos e obras em Florianópolis | I7: Formulário do serviço | J7: Service com areaServed | K7: Sem página extra. | L7: =COUNTIF('Mapa de Serviços'!$J:$J,$A7) -> 0 | M7: =COUNTIF('Mapa de Marcas'!$L:$L,$A7) -> 0 | N7: =COUNTIF('Camadas Programáticas'!$I$15:$I$272,$A7) -> 18 | O7: =COUNTIF(Arquitetura!$E:$E,$A7) -> 0
A8: Página local | B8: Camadas programáticas | C8: Serviço combinado com cidade, ou processo em órgão municipal. | D8: Capturar buscas com cidade. | E8: Transacional | F8: N4 | G8: /hub/servico/cidade/ | H8: Obras na cidade, regras locais, prazo de atendimento, depoimento local | I8: Formulário do serviço | J8: Service, LocalBusiness com areaServed | K8: Só com conteúdo único e obra ou demanda comprovada. | L8: =COUNTIF('Mapa de Serviços'!$J:$J,$A8) -> 0 | M8: =COUNTIF('Mapa de Marcas'!$L:$L,$A8) -> 11 | N8: =COUNTIF('Camadas Programáticas'!$I$15:$I$272,$A8) -> 180 | O8: =COUNTIF(Arquitetura!$E:$E,$A8) -> 0
A9: Página local de bairro | B9: Camadas programáticas | C9: Serviço de obra combinado com bairro de alto padrão. | D9: Capturar buscas hiperlocais de alto padrão. | E9: Transacional | F9: N4 | G9: /hub/servico/bairro/ | H9: Obra no bairro, particularidades de solo e condomínio, fotos | I9: Formulário do serviço | J9: Service com areaServed | K9: Só com obra da Vaff no bairro. | L9: =COUNTIF('Mapa de Serviços'!$J:$J,$A9) -> 0 | M9: =COUNTIF('Mapa de Marcas'!$L:$L,$A9) -> 0 | N9: =COUNTIF('Camadas Programáticas'!$I$15:$I$272,$A9) -> 60 | O9: =COUNTIF(Arquitetura!$E:$E,$A9) -> 0
A10: Página de categoria de marca | B10: Marcas e sistemas | C10: Lista as marcas de uma categoria e os serviços ligados. | D10: Entrada para quem busca pelo tipo de produto. | E10: Comercial | F10: N2 | G10: /marcas-e-sistemas/categoria/ | H10: Explicação da categoria, marcas, serviços relacionados | I10: Solicitar proposta | J10: ItemList, BreadcrumbList | K10: Uma por categoria aprovada. | L10: =COUNTIF('Mapa de Serviços'!$J:$J,$A10) -> 0 | M10: =COUNTIF('Mapa de Marcas'!$L:$L,$A10) -> 24 | N10: =COUNTIF('Camadas Programáticas'!$I$15:$I$272,$A10) -> 0 | O10: =COUNTIF(Arquitetura!$E:$E,$A10) -> 24
A11: Página de marca | B11: Marcas e sistemas | C11: Página de uma marca, companhia ou operadora. | D11: Capturar a busca pelo nome da marca e levar ao serviço. | E11: Comercial | F11: N3 ou N4 | G11: /marcas-e-sistemas/categoria/marca/ ou /hub/servico/marca/ | H11: O que a Vaff faz com a marca, serviços em seções, orientação neutra, obra, CTA, aviso de não vínculo | I11: Solicitar proposta | J11: BreadcrumbList, FAQPage | K11: Criar para marcas aprovadas; nunca sugerir parceria inexistente. | L11: =COUNTIF('Mapa de Serviços'!$J:$J,$A11) -> 0 | M11: =COUNTIF('Mapa de Marcas'!$L:$L,$A11) -> 164 | N11: =COUNTIF('Camadas Programáticas'!$I$15:$I$272,$A11) -> 0 | O11: =COUNTIF(Arquitetura!$E:$E,$A11) -> 23
A12: Página de marca por serviço | B12: Marcas e sistemas | C12: Combinação de marca e serviço com demanda própria. | D12: Capturar a busca específica, como laudo de um produto de uma marca. | E12: Transacional | F12: N4 | G12: /marcas-e-sistemas/categoria/marca/servico/ | H12: Problema típico, diagnóstico, garantia do fabricante, caso real, CTA | I12: Formulário do serviço | J12: Service, FAQPage | K12: Só para marcas em destaque e com conteúdo único. | L12: =COUNTIF('Mapa de Serviços'!$J:$J,$A12) -> 0 | M12: =COUNTIF('Mapa de Marcas'!$L:$L,$A12) -> 47 | N12: =COUNTIF('Camadas Programáticas'!$I$15:$I$272,$A12) -> 0 | O12: =COUNTIF(Arquitetura!$E:$E,$A12) -> 1
A13: Seção na página da marca | B13: Marcas e sistemas | C13: Combinação de marca e serviço sem demanda para página própria. | D13: Cobrir o termo sem criar página fina. | E13: Comercial | F13: Seção | G13: /marcas-e-sistemas/categoria/marca/#servico | H13: Subtítulo, parágrafo, link para o serviço âncora | I13: CTA da página | J13: Incluído no FAQPage | K13: Nunca criar URL própria. | L13: =COUNTIF('Mapa de Serviços'!$J:$J,$A13) -> 0 | M13: =COUNTIF('Mapa de Marcas'!$L:$L,$A13) -> 214 | N13: =COUNTIF('Camadas Programáticas'!$I$15:$I$272,$A13) -> 0 | O13: =COUNTIF(Arquitetura!$E:$E,$A13) -> 0
... A28: Formulário qualificado | B28: Conversão | C28: Formulário por tipo de demanda. | D28: Qualificar antes da conversa. | E28: Transacional | F28: N2 | G28: /solicitar-proposta/tipo/ | H28: Campos obrigatórios, fotos, prazo de resposta | I28: Enviar | J28: ContactPage | K28: Um por tipo de demanda. | L28: =COUNTIF('Mapa de Serviços'!$J:$J,$A28) -> 0 | M28: =COUNTIF('Mapa de Marcas'!$L:$L,$A28) -> 0 | N28: =COUNTIF('Camadas Programáticas'!$I$15:$I$272,$A28) -> 0 | O28: =COUNTIF(Arquitetura!$E:$E,$A28) -> 5

Sheet Hubs
A1: Hub | B1: URL do hub | C1: Palavra pilar | D1: O que reúne | E1: Personas principais | F1: Total de termos | G1: Páginas próprias | H1: Seções em outras páginas | I1: Conteúdos | J1: Termos de marca e companhia | K1: Prioridade alta | L1: Lacunas na concorrência | M1: Aprovados pela Vaff
A2: Construção | B2: /construcao/ | C2: Construtora de alto padrão em Florianópolis | D2: Execução de casas, edifícios e obras comerciais do zero, incluindo sistemas construtivos, fundações e áreas externas. | E2: Patrimonialista Ocupado, Recém-Chegado, Construtor por Paixão, Dono que Não Pode Parar, Incorporador Enxuto | F2: =COUNTIF('Mapa de Serviços'!$B:$B,$A2)+COUNTIF('Mapa de Marcas'!$D:$D,$A2) -> 137 | G2: =COUNTIFS('Mapa de Serviços'!$B:$B,$A2,'Mapa de Serviços'!$J:$J,"Página pilar")+COUNTIFS('Mapa de Marcas'!$D:$D,$A2,'Mapa de Marcas'!$L:$L,"Página pilar")+COUNTIFS('Mapa de Serviços'!$B:$B,$A2,'Mapa de Serviços'!$J:$J,"Página de subhub")+COUNTIFS('Mapa de Marcas'!$D:$D,$A2,'Mapa de Marcas'!$L:$L,"Página de subhub")+COUNTIFS('Mapa de Serviços'!$B:$B,$A2,'Mapa de Serviços'!$J:$J,"Página de serviço")+COUNTIFS('Mapa de Marcas'!$D:$D,$A2,'Mapa de Marcas'!$L:$L,"Página de serviço")+COUNTIFS('Mapa de Serviços'!$B:$B,$A2,'Mapa de Serviços'!$J:$J,"Página de sistema construtivo")+COUNTIFS('Mapa de Marcas'!$D:$D,$A2,'Mapa de Marcas'!$L:$L,"Página de sistema construtivo")+COUNTIFS('Mapa de Serviços'!$B:$B,$A2,'Mapa de Serviços'!$J:$J,"Página de marca")+COUNTIFS('Mapa de Marcas'!$D:$D,$A2,'Mapa de Marcas'!$L:$L,"Página de marca")+COUNTIFS('Mapa de Serviços'!$B:$B,$A2,'Mapa de Serviços'!$J:$J,"Página local")+COUNTIFS('Mapa de Marcas'!$D:$D,$A2,'Mapa de Marcas'!$L:$L,"Página local")+COUNTIFS('Mapa de Serviços'!$B:$B,$A2,'Mapa de Serviços'!$J:$J,"Página de categoria de marca")+COUNTIFS('Mapa de Marcas'!$D:$D,$A2,'Mapa de Marcas'!$L:$L,"Página de categoria de marca")+COUNTIFS('Mapa de Serviços'!$B:$B,$A2,'Mapa de Serviços'!$J:$J,"Página de marca por serviço")+COUNTIFS('Mapa de Marcas'!$D:$D,$A2,'Mapa de Marcas'!$L:$L,"Página de marca por serviço")+COUNTIFS('Mapa de Serviços'!$B:$B,$A2,'Mapa de Serviços'!$J:$J,"Página de sistema por serviço")+COUNTIFS('Mapa de Marcas'!$D:$D,$A2,'Mapa de Marcas'!$L:$L,"Página de sistema por serviço") -> 113 | H2: =COUNTIFS('Mapa de Serviços'!$B:$B,$A2,'Mapa de Serviços'!$J:$J,"Seção dentro de outra página")+COUNTIFS('Mapa de Marcas'!$D:$D,$A2,'Mapa de Marcas'!$L:$L,"Seção dentro de outra página")+COUNTIFS('Mapa de Serviços'!$B:$B,$A2,'Mapa de Serviços'!$J:$J,"Seção na página da marca")+COUNTIFS('Mapa de Marcas'!$D:$D,$A2,'Mapa de Marcas'!$L:$L,"Seção na página da marca")+COUNTIFS('Mapa de Serviços'!$B:$B,$A2,'Mapa de Serviços'!$J:$J,"Seção na página do sistema")+COUNTIFS('Mapa de Marcas'!$D:$D,$A2,'Mapa de Marcas'!$L:$L,"Seção na página do sistema")+COUNTIFS('Mapa de Serviços'!$B:$B,$A2,'Mapa de Serviços'!$J:$J,"Seção em página de serviço")+COUNTIFS('Mapa de Marcas'!$D:$D,$A2,'Mapa de Marcas'!$L:$L,"Seção em página de serviço") -> 2 | I2: =COUNTIFS('Mapa de Serviços'!$B:$B,$A2,'Mapa de Serviços'!$J:$J,"Artigo de blog")+COUNTIFS('Mapa de Marcas'!$D:$D,$A2,'Mapa de Marcas'!$L:$L,"Artigo de blog")+COUNTIFS('Mapa de Serviços'!$B:$B,$A2,'Mapa de Serviços'!$J:$J,"Guia para download")+COUNTIFS('Mapa de Marcas'!$D:$D,$A2,'Mapa de Marcas'!$L:$L,"Guia para download")+COUNTIFS('Mapa de Serviços'!$B:$B,$A2,'Mapa de Serviços'!$J:$J,"Calculadora")+COUNTIFS('Mapa de Marcas'!$D:$D,$A2,'Mapa de Marcas'!$L:$L,"Calculadora")+COUNTIFS('Mapa de Serviços'!$B:$B,$A2,'Mapa de Serviços'!$J:$J,"Página pilar de conteúdo")+COUNTIFS('Mapa de Marcas'!$D:$D,$A2,'Mapa de Marcas'!$L:$L,"Página pilar de conteúdo") -> 14 | J2: =COUNTIF('Mapa de Marcas'!$D:$D,$A2) -> 8 | K2: =COUNTIFS('Mapa de Serviços'!$B:$B,$A2,'Mapa de Serviços'!$P:$P,"Alta")+COUNTIFS('Mapa de Marcas'!$D:$D,$A2,'Mapa de Marcas'!$Q:$Q,"Alta") -> 11 | L2: =COUNTIFS('Mapa de Serviços'!$B:$B,$A2,'Mapa de Serviços'!$Q:$Q,"Lacuna")+COUNTIFS('Mapa de Marcas'!$D:$D,$A2,'Mapa de Marcas'!$R:$R,"Lacuna") -> 0 | M2: =COUNTIFS('Mapa de Serviços'!$B:$B,$A2,'Mapa de Serviços'!$S:$S,"Aprovar")+COUNTIFS('Mapa de Marcas'!$D:$D,$A2,'Mapa de Marcas'!$T:$T,"Aprovar") -> 0
A3: Reformas | B3: /reformas/ | C3: Empresa de reforma de alto padrão | D3: Reformas residenciais, comerciais e por ambiente, retrofit, acessibilidade e acabamentos. | E3: Patrimonialista Ocupado, Recém-Chegado, Proprietário à Distância, Dono que Não Pode Parar, Investidor de Renda | F3: =COUNTIF('Mapa de Serviços'!$B:$B,$A3)+COUNTIF('Mapa de Marcas'!$D:$D,$A3) -> 155 | G3: =COUNTIFS('Mapa de Serviços'!$B:$B,$A3,'Mapa de Serviços'!$J:$J,"Página pilar")+COUNTIFS('Mapa de Marcas'!$D:$D,$A3,'Mapa de Marcas'!$L:$L,"Página pilar")+COUNTIFS('Mapa de Serviços'!$B:$B,$A3,'Mapa de Serviços'!$J:$J,"Página de subhub")+COUNTIFS('Mapa de Marcas'!$D:$D,$A3,'Mapa de Marcas'!$L:$L,"Página de subhub")+COUNTIFS('Mapa de Serviços'!$B:$B,$A3,'Mapa de Serviços'!$J:$J,"Página de serviço")+COUNTIFS('Mapa de Marcas'!$D:$D,$A3,'Mapa de Marcas'!$L:$L,"Página de serviço")+COUNTIFS('Mapa de Serviços'!$B:$B,$A3,'Mapa de Serviços'!$J:$J,"Página de sistema construtivo")+COUNTIFS('Mapa de Marcas'!$D:$D,$A3,'Mapa de Marcas'!$L:$L,"Página de sistema construtivo")+COUNTIFS('Mapa de Serviços'!$B:$B,$A3,'Mapa de Serviços'!$J:$J,"Página de marca")+COUNTIFS('Mapa de Marcas'!$D:$D,$A3,'Mapa de Marcas'!$L:$L,"Página de marca")+COUNTIFS('Mapa de Serviços'!$B:$B,$A3,'Mapa de Serviços'!$J:$J,"Página local")+COUNTIFS('Mapa de Marcas'!$D:$D,$A3,'Mapa de Marcas'!$L:$L,"Página local")+COUNTIFS('Mapa de Serviços'!$B:$B,$A3,'Mapa de Serviços'!$J:$J,"Página de categoria de marca")+COUNTIFS('Mapa de Marcas'!$D:$D,$A3,'Mapa de Marcas'!$L:$L,"Página de categoria de marca")+COUNTIFS('Mapa de Serviços'!$B:$B,$A3,'Mapa de Serviços'!$J:$J,"Página de marca por serviço")+COUNTIFS('Mapa de Marcas'!$D:$D,$A3,'Mapa de Marcas'!$L:$L,"Página de marca por serviço")+COUNTIFS('Mapa de Serviços'!$B:$B,$A3,'Mapa de Serviços'!$J:$J,"Página de sistema por serviço")+COUNTIFS('Mapa de Marcas'!$D:$D,$A3,'Mapa de Marcas'!$L:$L,"Página de sistema por serviço") -> 126 | H3: =COUNTIFS('Mapa de Serviços'!$B:$B,$A3,'Mapa de Serviços'!$J:$J,"Seção dentro de outra página")+COUNTIFS('Mapa de Marcas'!$D:$D,$A3,'Mapa de Marcas'!$L:$L,"Seção dentro de outra página")+COUNTIFS('Mapa de Serviços'!$B:$B,$A3,'Mapa de Serviços'!$J:$J,"Seção na página da marca")+COUNTIFS('Mapa de Marcas'!$D:$D,$A3,'Mapa de Marcas'!$L:$L,"Seção na página da marca")+COUNTIFS('Mapa de Serviços'!$B:$B,$A3,'Mapa de Serviços'!$J:$J,"Seção na página do sistema")+COUNTIFS('Mapa de Marcas'!$D:$D,$A3,'Mapa de Marcas'!$L:$L,"Seção na página do sistema")+COUNTIFS('Mapa de Serviços'!$B:$B,$A3,'Mapa de Serviços'!$J:$J,"Seção em página de serviço")+COUNTIFS('Mapa de Marcas'!$D:$D,$A3,'Mapa de Marcas'!$L:$L,"Seção em página de serviço") -> 2 | I3: =COUNTIFS('Mapa de Serviços'!$B:$B,$A3,'Mapa de Serviços'!$J:$J,"Artigo de blog")+COUNTIFS('Mapa de Marcas'!$D:$D,$A3,'Mapa de Marcas'!$L:$L,"Artigo de blog")+COUNTIFS('Mapa de Serviços'!$B:$B,$A3,'Mapa de Serviços'!$J:$J,"Guia para download")+COUNTIFS('Mapa de Marcas'!$D:$D,$A3,'Mapa de Marcas'!$L:$L,"Guia para download")+COUNTIFS('Mapa de Serviços'!$B:$B,$A3,'Mapa de Serviços'!$J:$J,"Calculadora")+COUNTIFS('Mapa de Marcas'!$D:$D,$A3,'Mapa de Marcas'!$L:$L,"Calculadora")+COUNTIFS('Mapa de Serviços'!$B:$B,$A3,'Mapa de Serviços'!$J:$J,"Página pilar de conteúdo")+COUNTIFS('Mapa de Marcas'!$D:$D,$A3,'Mapa de Marcas'!$L:$L,"Página pilar de conteúdo") -> 22 | J3: =COUNTIF('Mapa de Marcas'!$D:$D,$A3) -> 13 | K3: =COUNTIFS('Mapa de Serviços'!$B:$B,$A3,'Mapa de Serviços'!$P:$P,"Alta")+COUNTIFS('Mapa de Marcas'!$D:$D,$A3,'Mapa de Marcas'!$Q:$Q,"Alta") -> 14 | L3: =COUNTIFS('Mapa de Serviços'!$B:$B,$A3,'Mapa de Serviços'!$Q:$Q,"Lacuna")+COUNTIFS('Mapa de Marcas'!$D:$D,$A3,'Mapa de Marcas'!$R:$R,"Lacuna") -> 2 | M3: =COUNTIFS('Mapa de Serviços'!$B:$B,$A3,'Mapa de Serviços'!$S:$S,"Aprovar")+COUNTIFS('Mapa de Marcas'!$D:$D,$A3,'Mapa de Marcas'!$T:$T,"Aprovar") -> 0
A4: Projetos de Engenharia | B4: /projetos/ | C4: Projetos de engenharia | D4: Projetos complementares, estruturais, aprovações, compatibilização, orçamento e planejamento técnico. | E4: Travado pela Burocracia, Arquiteto, Incorporador Enxuto, Patrimonialista Ocupado | F4: =COUNTIF('Mapa de Serviços'!$B:$B,$A4)+COUNTIF('Mapa de Marcas'!$D:$D,$A4) -> 132 | G4: =COUNTIFS('Mapa de Serviços'!$B:$B,$A4,'Mapa de Serviços'!$J:$J,"Página pilar")+COUNTIFS('Mapa de Marcas'!$D:$D,$A4,'Mapa de Marcas'!$L:$L,"Página pilar")+COUNTIFS('Mapa de Serviços'!$B:$B,$A4,'Mapa de Serviços'!$J:$J,"Página de subhub")+COUNTIFS('Mapa de Marcas'!$D:$D,$A4,'Mapa de Marcas'!$L:$L,"Página de subhub")+COUNTIFS('Mapa de Serviços'!$B:$B,$A4,'Mapa de Serviços'!$J:$J,"Página de serviço")+COUNTIFS('Mapa de Marcas'!$D:$D,$A4,'Mapa de Marcas'!$L:$L,"Página de serviço")+COUNTIFS('Mapa de Serviços'!$B:$B,$A4,'Mapa de Serviços'!$J:$J,"Página de sistema construtivo")+COUNTIFS('Mapa de Marcas'!$D:$D,$A4,'Mapa de Marcas'!$L:$L,"Página de sistema construtivo")+COUNTIFS('Mapa de Serviços'!$B:$B,$A4,'Mapa de Serviços'!$J:$J,"Página de marca")+COUNTIFS('Mapa de Marcas'!$D:$D,$A4,'Mapa de Marcas'!$L:$L,"Página de marca")+COUNTIFS('Mapa de Serviços'!$B:$B,$A4,'Mapa de Serviços'!$J:$J,"Página local")+COUNTIFS('Mapa de Marcas'!$D:$D,$A4,'Mapa de Marcas'!$L:$L,"Página local")+COUNTIFS('Mapa de Serviços'!$B:$B,$A4,'Mapa de Serviços'!$J:$J,"Página de categoria de marca")+COUNTIFS('Mapa de Marcas'!$D:$D,$A4,'Mapa de Marcas'!$L:$L,"Página de categoria de marca")+COUNTIFS('Mapa de Serviços'!$B:$B,$A4,'Mapa de Serviços'!$J:$J,"Página de marca por serviço")+COUNTIFS('Mapa de Marcas'!$D:$D,$A4,'Mapa de Marcas'!$L:$L,"Página de marca por serviço")+COUNTIFS('Mapa de Serviços'!$B:$B,$A4,'Mapa de Serviços'!$J:$J,"Página de sistema por serviço")+COUNTIFS('Mapa de Marcas'!$D:$D,$A4,'Mapa de Marcas'!$L:$L,"Página de sistema por serviço") -> 114 | H4: =COUNTIFS('Mapa de Serviços'!$B:$B,$A4,'Mapa de Serviços'!$J:$J,"Seção dentro de outra página")+COUNTIFS('Mapa de Marcas'!$D:$D,$A4,'Mapa de Marcas'!$L:$L,"Seção dentro de outra página")+COUNTIFS('Mapa de Serviços'!$B:$B,$A4,'Mapa de Serviços'!$J:$J,"Seção na página da marca")+COUNTIFS('Mapa de Marcas'!$D:$D,$A4,'Mapa de Marcas'!$L:$L,"Seção na página da marca")+COUNTIFS('Mapa de Serviços'!$B:$B,$A4,'Mapa de Serviços'!$J:$J,"Seção na página do sistema")+COUNTIFS('Mapa de Marcas'!$D:$D,$A4,'Mapa de Marcas'!$L:$L,"Seção na página do sistema")+COUNTIFS('Mapa de Serviços'!$B:$B,$A4,'Mapa de Serviços'!$J:$J,"Seção em página de serviço")+COUNTIFS('Mapa de Marcas'!$D:$D,$A4,'Mapa de Marcas'!$L:$L,"Seção em página de serviço") -> 7 | I4: =COUNTIFS('Mapa de Serviços'!$B:$B,$A4,'Mapa de Serviços'!$J:$J,"Artigo de blog")+COUNTIFS('Mapa de Marcas'!$D:$D,$A4,'Mapa de Marcas'!$L:$L,"Artigo de blog")+COUNTIFS('Mapa de Serviços'!$B:$B,$A4,'Mapa de Serviços'!$J:$J,"Guia para download")+COUNTIFS('Mapa de Marcas'!$D:$D,$A4,'Mapa de Marcas'!$L:$L,"Guia para download")+COUNTIFS('Mapa de Serviços'!$B:$B,$A4,'Mapa de Serviços'!$J:$J,"Calculadora")+COUNTIFS('Mapa de Marcas'!$D:$D,$A4,'Mapa de Marcas'!$L:$L,"Calculadora")+COUNTIFS('Mapa de Serviços'!$B:$B,$A4,'Mapa de Serviços'!$J:$J,"Página pilar de conteúdo")+COUNTIFS('Mapa de Marcas'!$D:$D,$A4,'Mapa de Marcas'!$L:$L,"Página pilar de conteúdo") -> 11 | J4: =COUNTIF('Mapa de Marcas'!$D:$D,$A4) -> 6 | K4: =COUNTIFS('Mapa de Serviços'!$B:$B,$A4,'Mapa de Serviços'!$P:$P,"Alta")+COUNTIFS('Mapa de Marcas'!$D:$D,$A4,'Mapa de Marcas'!$Q:$Q,"Alta") -> 19 | L4: =COUNTIFS('Mapa de Serviços'!$B:$B,$A4,'Mapa de Serviços'!$Q:$Q,"Lacuna")+COUNTIFS('Mapa de Marcas'!$D:$D,$A4,'Mapa de Marcas'!$R:$R,"Lacuna") -> 0 | M4: =COUNTIFS('Mapa de Serviços'!$B:$B,$A4,'Mapa de Serviços'!$S:$S,"Aprovar")+COUNTIFS('Mapa de Marcas'!$D:$D,$A4,'Mapa de Marcas'!$T:$T,"Aprovar") -> 0
A5: Laudos Técnicos | B5: /laudos-tecnicos/ | C5: Laudo técnico de engenharia | D5: Laudos de patologias, estrutura, instalações, sinistros, vizinhança e finalidades legais. | E5: Assustado, Comprador Cauteloso, Vítima de Sinistro, Síndico Profissional, Advogado | F5: =COUNTIF('Mapa de Serviços'!$B:$B,$A5)+COUNTIF('Mapa de Marcas'!$D:$D,$A5) -> 130 | G5: =COUNTIFS('Mapa de Serviços'!$B:$B,$A5,'Mapa de Serviços'!$J:$J,"Página pilar")+COUNTIFS('Mapa de Marcas'!$D:$D,$A5,'Mapa de Marcas'!$L:$L,"Página pilar")+COUNTIFS('Mapa de Serviços'!$B:$B,$A5,'Mapa de Serviços'!$J:$J,"Página de subhub")+COUNTIFS('Mapa de Marcas'!$D:$D,$A5,'Mapa de Marcas'!$L:$L,"Página de subhub")+COUNTIFS('Mapa de Serviços'!$B:$B,$A5,'Mapa de Serviços'!$J:$J,"Página de serviço")+COUNTIFS('Mapa de Marcas'!$D:$D,$A5,'Mapa de Marcas'!$L:$L,"Página de serviço")+COUNTIFS('Mapa de Serviços'!$B:$B,$A5,'Mapa de Serviços'!$J:$J,"Página de sistema construtivo")+COUNTIFS('Mapa de Marcas'!$D:$D,$A5,'Mapa de Marcas'!$L:$L,"Página de sistema construtivo")+COUNTIFS('Mapa de Serviços'!$B:$B,$A5,'Mapa de Serviços'!$J:$J,"Página de marca")+COUNTIFS('Mapa de Marcas'!$D:$D,$A5,'Mapa de Marcas'!$L:$L,"Página de marca")+COUNTIFS('Mapa de Serviços'!$B:$B,$A5,'Mapa de Serviços'!$J:$J,"Página local")+COUNTIFS('Mapa de Marcas'!$D:$D,$A5,'Mapa de Marcas'!$L:$L,"Página local")+COUNTIFS('Mapa de Serviços'!$B:$B,$A5,'Mapa de Serviços'!$J:$J,"Página de categoria de marca")+COUNTIFS('Mapa de Marcas'!$D:$D,$A5,'Mapa de Marcas'!$L:$L,"Página de categoria de marca")+COUNTIFS('Mapa de Serviços'!$B:$B,$A5,'Mapa de Serviços'!$J:$J,"Página de marca por serviço")+COUNTIFS('Mapa de Marcas'!$D:$D,$A5,'Mapa de Marcas'!$L:$L,"Página de marca por serviço")+COUNTIFS('Mapa de Serviços'!$B:$B,$A5,'Mapa de Serviços'!$J:$J,"Página de sistema por serviço")+COUNTIFS('Mapa de Marcas'!$D:$D,$A5,'Mapa de Marcas'!$L:$L,"Página de sistema por serviço") -> 92 | H5: =COUNTIFS('Mapa de Serviços'!$B:$B,$A5,'Mapa de Serviços'!$J:$J,"Seção dentro de outra página")+COUNTIFS('Mapa de Marcas'!$D:$D,$A5,'Mapa de Marcas'!$L:$L,"Seção dentro de outra página")+COUNTIFS('Mapa de Serviços'!$B:$B,$A5,'Mapa de Serviços'!$J:$J,"Seção na página da marca")+COUNTIFS('Mapa de Marcas'!$D:$D,$A5,'Mapa de Marcas'!$L:$L,"Seção na página da marca")+COUNTIFS('Mapa de Serviços'!$B:$B,$A5,'Mapa de Serviços'!$J:$J,"Seção na página do sistema")+COUNTIFS('Mapa de Marcas'!$D:$D,$A5,'Mapa de Marcas'!$L:$L,"Seção na página do sistema")+COUNTIFS('Mapa de Serviços'!$B:$B,$A5,'Mapa de Serviços'!$J:$J,"Seção em página de serviço")+COUNTIFS('Mapa de Marcas'!$D:$D,$A5,'Mapa de Marcas'!$L:$L,"Seção em página de serviço") -> 22 | I5: =COUNTIFS('Mapa de Serviços'!$B:$B,$A5,'Mapa de Serviços'!$J:$J,"Artigo de blog")+COUNTIFS('Mapa de Marcas'!$D:$D,$A5,'Mapa de Marcas'!$L:$L,"Artigo de blog")+COUNTIFS('Mapa de Serviços'!$B:$B,$A5,'Mapa de Serviços'!$J:$J,"Guia para download")+COUNTIFS('Mapa de Marcas'!$D:$D,$A5,'Mapa de Marcas'!$L:$L,"Guia para download")+COUNTIFS('Mapa de Serviços'!$B:$B,$A5,'Mapa de Serviços'!$J:$J,"Calculadora")+COUNTIFS('Mapa de Marcas'!$D:$D,$A5,'Mapa de Marcas'!$L:$L,"Calculadora")+COUNTIFS('Mapa de Serviços'!$B:$B,$A5,'Mapa de Serviços'!$J:$J,"Página pilar de conteúdo")+COUNTIFS('Mapa de Marcas'!$D:$D,$A5,'Mapa de Marcas'!$L:$L,"Página pilar de conteúdo") -> 16 | J5: =COUNTIF('Mapa de Marcas'!$D:$D,$A5) -> 32 | K5: =COUNTIFS('Mapa de Serviços'!$B:$B,$A5,'Mapa de Serviços'!$P:$P,"Alta")+COUNTIFS('Mapa de Marcas'!$D:$D,$A5,'Mapa de Marcas'!$Q:$Q,"Alta") -> 17 | L5: =COUNTIFS('Mapa de Serviços'!$B:$B,$A5,'Mapa de Serviços'!$Q:$Q,"Lacuna")+COUNTIFS('Mapa de Marcas'!$D:$D,$A5,'Mapa de Marcas'!$R:$R,"Lacuna") -> 42 | M5: =COUNTIFS('Mapa de Serviços'!$B:$B,$A5,'Mapa de Serviços'!$S:$S,"Aprovar")+COUNTIFS('Mapa de Marcas'!$D:$D,$A5,'Mapa de Marcas'!$T:$T,"Aprovar") -> 0
A6: Vistorias e Inspeções | B6: /vistorias-e-inspecoes/ | C6: Vistoria técnica de imóveis | D6: Vistorias de entrega, compra, locação, cautelares, inspeção predial e ensaios técnicos. | E6: Recebedor de Chaves, Comprador Cauteloso, Síndico Profissional, Vizinho de Obra | F6: =COUNTIF('Mapa de Serviços'!$B:$B,$A6)+COUNTIF('Mapa de Marcas'!$D:$D,$A6) -> 86 | G6: =COUNTIFS('Mapa de Serviços'!$B:$B,$A6,'Mapa de Serviços'!$J:$J,"Página pilar")+COUNTIFS('Mapa de Marcas'!$D:$D,$A6,'Mapa de Marcas'!$L:$L,"Página pilar")+COUNTIFS('Mapa de Serviços'!$B:$B,$A6,'Mapa de Serviços'!$J:$J,"Página de subhub")+COUNTIFS('Mapa de Marcas'!$D:$D,$A6,'Mapa de Marcas'!$L:$L,"Página de subhub")+COUNTIFS('Mapa de Serviços'!$B:$B,$A6,'Mapa de Serviços'!$J:$J,"Página de serviço")+COUNTIFS('Mapa de Marcas'!$D:$D,$A6,'Mapa de Marcas'!$L:$L,"Página de serviço")+COUNTIFS('Mapa de Serviços'!$B:$B,$A6,'Mapa de Serviços'!$J:$J,"Página de sistema construtivo")+COUNTIFS('Mapa de Marcas'!$D:$D,$A6,'Mapa de Marcas'!$L:$L,"Página de sistema construtivo")+COUNTIFS('Mapa de Serviços'!$B:$B,$A6,'Mapa de Serviços'!$J:$J,"Página de marca")+COUNTIFS('Mapa de Marcas'!$D:$D,$A6,'Mapa de Marcas'!$L:$L,"Página de marca")+COUNTIFS('Mapa de Serviços'!$B:$B,$A6,'Mapa de Serviços'!$J:$J,"Página local")+COUNTIFS('Mapa de Marcas'!$D:$D,$A6,'Mapa de Marcas'!$L:$L,"Página local")+COUNTIFS('Mapa de Serviços'!$B:$B,$A6,'Mapa de Serviços'!$J:$J,"Página de categoria de marca")+COUNTIFS('Mapa de Marcas'!$D:$D,$A6,'Mapa de Marcas'!$L:$L,"Página de categoria de marca")+COUNTIFS('Mapa de Serviços'!$B:$B,$A6,'Mapa de Serviços'!$J:$J,"Página de marca por serviço")+COUNTIFS('Mapa de Marcas'!$D:$D,$A6,'Mapa de Marcas'!$L:$L,"Página de marca por serviço")+COUNTIFS('Mapa de Serviços'!$B:$B,$A6,'Mapa de Serviços'!$J:$J,"Página de sistema por serviço")+COUNTIFS('Mapa de Marcas'!$D:$D,$A6,'Mapa de Marcas'!$L:$L,"Página de sistema por serviço") -> 64 | H6: =COUNTIFS('Mapa de Serviços'!$B:$B,$A6,'Mapa de Serviços'!$J:$J,"Seção dentro de outra página")+COUNTIFS('Mapa de Marcas'!$D:$D,$A6,'Mapa de Marcas'!$L:$L,"Seção dentro de outra página")+COUNTIFS('Mapa de Serviços'!$B:$B,$A6,'Mapa de Serviços'!$J:$J,"Seção na página da marca")+COUNTIFS('Mapa de Marcas'!$D:$D,$A6,'Mapa de Marcas'!$L:$L,"Seção na página da marca")+COUNTIFS('Mapa de Serviços'!$B:$B,$A6,'Mapa de Serviços'!$J:$J,"Seção na página do sistema")+COUNTIFS('Mapa de Marcas'!$D:$D,$A6,'Mapa de Marcas'!$L:$L,"Seção na página do sistema")+COUNTIFS('Mapa de Serviços'!$B:$B,$A6,'Mapa de Serviços'!$J:$J,"Seção em página de serviço")+COUNTIFS('Mapa de Marcas'!$D:$D,$A6,'Mapa de Marcas'!$L:$L,"Seção em página de serviço") -> 8 | I6: =COUNTIFS('Mapa de Serviços'!$B:$B,$A6,'Mapa de Serviços'!$J:$J,"Artigo de blog")+COUNTIFS('Mapa de Marcas'!$D:$D,$A6,'Mapa de Marcas'!$L:$L,"Artigo de blog")+COUNTIFS('Mapa de Serviços'!$B:$B,$A6,'Mapa de Serviços'!$J:$J,"Guia para download")+COUNTIFS('Mapa de Marcas'!$D:$D,$A6,'Mapa de Marcas'!$L:$L,"Guia para download")+COUNTIFS('Mapa de Serviços'!$B:$B,$A6,'Mapa de Serviços'!$J:$J,"Calculadora")+COUNTIFS('Mapa de Marcas'!$D:$D,$A6,'Mapa de Marcas'!$L:$L,"Calculadora")+COUNTIFS('Mapa de Serviços'!$B:$B,$A6,'Mapa de Serviços'!$J:$J,"Página pilar de conteúdo")+COUNTIFS('Mapa de Marcas'!$D:$D,$A6,'Mapa de Marcas'!$L:$L,"Página pilar de conteúdo") -> 11 | J6: =COUNTIF('Mapa de Marcas'!$D:$D,$A6) -> 27 | K6: =COUNTIFS('Mapa de Serviços'!$B:$B,$A6,'Mapa de Serviços'!$P:$P,"Alta")+COUNTIFS('Mapa de Marcas'!$D:$D,$A6,'Mapa de Marcas'!$Q:$Q,"Alta") -> 10 | L6: =COUNTIFS('Mapa de Serviços'!$B:$B,$A6,'Mapa de Serviços'!$Q:$Q,"Lacuna")+COUNTIFS('Mapa de Marcas'!$D:$D,$A6,'Mapa de Marcas'!$R:$R,"Lacuna") -> 1 | M6: =COUNTIFS('Mapa de Serviços'!$B:$B,$A6,'Mapa de Serviços'!$S:$S,"Aprovar")+COUNTIFS('Mapa de Marcas'!$D:$D,$A6,'Mapa de Marcas'!$T:$T,"Aprovar") -> 0
A7: Perícias e Avaliações | B7: /pericias-e-avaliacoes/ | C7: Perícia de engenharia | D7: Perícias judiciais e extrajudiciais, assistência técnica, pareceres e avaliação de imóveis. | E7: Advogado, Traído, Herdeiros, Comprador Cauteloso | F7: =COUNTIF('Mapa de Serviços'!$B:$B,$A7)+COUNTIF('Mapa de Marcas'!$D:$D,$A7) -> 58 | G7: =COUNTIFS('Mapa de Serviços'!$B:$B,$A7,'Mapa de Serviços'!$J:$J,"Página pilar")+COUNTIFS('Mapa de Marcas'!$D:$D,$A7,'Mapa de Marcas'!$L:$L,"Página pilar")+COUNTIFS('Mapa de Serviços'!$B:$B,$A7,'Mapa de Serviços'!$J:$J,"Página de subhub")+COUNTIFS('Mapa de Marcas'!$D:$D,$A7,'Mapa de Marcas'!$L:$L,"Página de subhub")+COUNTIFS('Mapa de Serviços'!$B:$B,$A7,'Mapa de Serviços'!$J:$J,"Página de serviço")+COUNTIFS('Mapa de Marcas'!$D:$D,$A7,'Mapa de Marcas'!$L:$L,"Página de serviço")+COUNTIFS('Mapa de Serviços'!$B:$B,$A7,'Mapa de Serviços'!$J:$J,"Página de sistema construtivo")+COUNTIFS('Mapa de Marcas'!$D:$D,$A7,'Mapa de Marcas'!$L:$L,"Página de sistema construtivo")+COUNTIFS('Mapa de Serviços'!$B:$B,$A7,'Mapa de Serviços'!$J:$J,"Página de marca")+COUNTIFS('Mapa de Marcas'!$D:$D,$A7,'Mapa de Marcas'!$L:$L,"Página de marca")+COUNTIFS('Mapa de Serviços'!$B:$B,$A7,'Mapa de Serviços'!$J:$J,"Página local")+COUNTIFS('Mapa de Marcas'!$D:$D,$A7,'Mapa de Marcas'!$L:$L,"Página local")+COUNTIFS('Mapa de Serviços'!$B:$B,$A7,'Mapa de Serviços'!$J:$J,"Página de categoria de marca")+COUNTIFS('Mapa de Marcas'!$D:$D,$A7,'Mapa de Marcas'!$L:$L,"Página de categoria de marca")+COUNTIFS('Mapa de Serviços'!$B:$B,$A7,'Mapa de Serviços'!$J:$J,"Página de marca por serviço")+COUNTIFS('Mapa de Marcas'!$D:$D,$A7,'Mapa de Marcas'!$L:$L,"Página de marca por serviço")+COUNTIFS('Mapa de Serviços'!$B:$B,$A7,'Mapa de Serviços'!$J:$J,"Página de sistema por serviço")+COUNTIFS('Mapa de Marcas'!$D:$D,$A7,'Mapa de Marcas'!$L:$L,"Página de sistema por serviço") -> 44 | H7: =COUNTIFS('Mapa de Serviços'!$B:$B,$A7,'Mapa de Serviços'!$J:$J,"Seção dentro de outra página")+COUNTIFS('Mapa de Marcas'!$D:$D,$A7,'Mapa de Marcas'!$L:$L,"Seção dentro de outra página")+COUNTIFS('Mapa de Serviços'!$B:$B,$A7,'Mapa de Serviços'!$J:$J,"Seção na página da marca")+COUNTIFS('Mapa de Marcas'!$D:$D,$A7,'Mapa de Marcas'!$L:$L,"Seção na página da marca")+COUNTIFS('Mapa de Serviços'!$B:$B,$A7,'Mapa de Serviços'!$J:$J,"Seção na página do sistema")+COUNTIFS('Mapa de Marcas'!$D:$D,$A7,'Mapa de Marcas'!$L:$L,"Seção na página do sistema")+COUNTIFS('Mapa de Serviços'!$B:$B,$A7,'Mapa de Serviços'!$J:$J,"Seção em página de serviço")+COUNTIFS('Mapa de Marcas'!$D:$D,$A7,'Mapa de Marcas'!$L:$L,"Seção em página de serviço") -> 5 | I7: =COUNTIFS('Mapa de Serviços'!$B:$B,$A7,'Mapa de Serviços'!$J:$J,"Artigo de blog")+COUNTIFS('Mapa de Marcas'!$D:$D,$A7,'Mapa de Marcas'!$L:$L,"Artigo de blog")+COUNTIFS('Mapa de Serviços'!$B:$B,$A7,'Mapa de Serviços'!$J:$J,"Guia para download")+COUNTIFS('Mapa de Marcas'!$D:$D,$A7,'Mapa de Marcas'!$L:$L,"Guia para download")+COUNTIFS('Mapa de Serviços'!$B:$B,$A7,'Mapa de Serviços'!$J:$J,"Calculadora")+COUNTIFS('Mapa de Marcas'!$D:$D,$A7,'Mapa de Marcas'!$L:$L,"Calculadora")+COUNTIFS('Mapa de Serviços'!$B:$B,$A7,'Mapa de Serviços'!$J:$J,"Página pilar de conteúdo")+COUNTIFS('Mapa de Marcas'!$D:$D,$A7,'Mapa de Marcas'!$L:$L,"Página pilar de conteúdo") -> 7 | J7: =COUNTIF('Mapa de Marcas'!$D:$D,$A7) -> 15 | K7: =COUNTIFS('Mapa de Serviços'!$B:$B,$A7,'Mapa de Serviços'!$P:$P,"Alta")+COUNTIFS('Mapa de Marcas'!$D:$D,$A7,'Mapa de Marcas'!$Q:$Q,"Alta") -> 5 | L7: =COUNTIFS('Mapa de Serviços'!$B:$B,$A7,'Mapa de Serviços'!$Q:$Q,"Lacuna")+COUNTIFS('Mapa de Marcas'!$D:$D,$A7,'Mapa de Marcas'!$R:$R,"Lacuna") -> 1 | M7: =COUNTIFS('Mapa de Serviços'!$B:$B,$A7,'Mapa de Serviços'!$S:$S,"Aprovar")+COUNTIFS('Mapa de Marcas'!$D:$D,$A7,'Mapa de Marcas'!$T:$T,"Aprovar") -> 0
A8: Gestão e Fiscalização de Obras | B8: /gestao-de-obras/ | C8: Gestão de obras | D8: Gestão, administração, fiscalização, auditoria, controle e responsabilidade técnica de obras. | E8: Patrimonialista Ocupado, Proprietário à Distância, Incorporador Enxuto, Síndico Profissional, Traído | F8: =COUNTIF('Mapa de Serviços'!$B:$B,$A8)+COUNTIF('Mapa de Marcas'!$D:$D,$A8) -> 85 | G8: =COUNTIFS('Mapa de Serviços'!$B:$B,$A8,'Mapa de Serviços'!$J:$J,"Página pilar")+COUNTIFS('Mapa de Marcas'!$D:$D,$A8,'Mapa de Marcas'!$L:$L,"Página pilar")+COUNTIFS('Mapa de Serviços'!$B:$B,$A8,'Mapa de Serviços'!$J:$J,"Página de subhub")+COUNTIFS('Mapa de Marcas'!$D:$D,$A8,'Mapa de Marcas'!$L:$L,"Página de subhub")+COUNTIFS('Mapa de Serviços'!$B:$B,$A8,'Mapa de Serviços'!$J:$J,"Página de serviço")+COUNTIFS('Mapa de Marcas'!$D:$D,$A8,'Mapa de Marcas'!$L:$L,"Página de serviço")+COUNTIFS('Mapa de Serviços'!$B:$B,$A8,'Mapa de Serviços'!$J:$J,"Página de sistema construtivo")+COUNTIFS('Mapa de Marcas'!$D:$D,$A8,'Mapa de Marcas'!$L:$L,"Página de sistema construtivo")+COUNTIFS('Mapa de Serviços'!$B:$B,$A8,'Mapa de Serviços'!$J:$J,"Página de marca")+COUNTIFS('Mapa de Marcas'!$D:$D,$A8,'Mapa de Marcas'!$L:$L,"Página de marca")+COUNTIFS('Mapa de Serviços'!$B:$B,$A8,'Mapa de Serviços'!$J:$J,"Página local")+COUNTIFS('Mapa de Marcas'!$D:$D,$A8,'Mapa de Marcas'!$L:$L,"Página local")+COUNTIFS('Mapa de Serviços'!$B:$B,$A8,'Mapa de Serviços'!$J:$J,"Página de categoria de marca")+COUNTIFS('Mapa de Marcas'!$D:$D,$A8,'Mapa de Marcas'!$L:$L,"Página de categoria de marca")+COUNTIFS('Mapa de Serviços'!$B:$B,$A8,'Mapa de Serviços'!$J:$J,"Página de marca por serviço")+COUNTIFS('Mapa de Marcas'!$D:$D,$A8,'Mapa de Marcas'!$L:$L,"Página de marca por serviço")+COUNTIFS('Mapa de Serviços'!$B:$B,$A8,'Mapa de Serviços'!$J:$J,"Página de sistema por serviço")+COUNTIFS('Mapa de Marcas'!$D:$D,$A8,'Mapa de Marcas'!$L:$L,"Página de sistema por serviço") -> 64 | H8: =COUNTIFS('Mapa de Serviços'!$B:$B,$A8,'Mapa de Serviços'!$J:$J,"Seção dentro de outra página")+COUNTIFS('Mapa de Marcas'!$D:$D,$A8,'Mapa de Marcas'!$L:$L,"Seção dentro de outra página")+COUNTIFS('Mapa de Serviços'!$B:$B,$A8,'Mapa de Serviços'!$J:$J,"Seção na página da marca")+COUNTIFS('Mapa de Marcas'!$D:$D,$A8,'Mapa de Marcas'!$L:$L,"Seção na página da marca")+COUNTIFS('Mapa de Serviços'!$B:$B,$A8,'Mapa de Serviços'!$J:$J,"Seção na página do sistema")+COUNTIFS('Mapa de Marcas'!$D:$D,$A8,'Mapa de Marcas'!$L:$L,"Seção na página do sistema")+COUNTIFS('Mapa de Serviços'!$B:$B,$A8,'Mapa de Serviços'!$J:$J,"Seção em página de serviço")+COUNTIFS('Mapa de Marcas'!$D:$D,$A8,'Mapa de Marcas'!$L:$L,"Seção em página de serviço") -> 11 | I8: =COUNTIFS('Mapa de Serviços'!$B:$B,$A8,'Mapa de Serviços'!$J:$J,"Artigo de blog")+COUNTIFS('Mapa de Marcas'!$D:$D,$A8,'Mapa de Marcas'!$L:$L,"Artigo de blog")+COUNTIFS('Mapa de Serviços'!$B:$B,$A8,'Mapa de Serviços'!$J:$J,"Guia para download")+COUNTIFS('Mapa de Marcas'!$D:$D,$A8,'Mapa de Marcas'!$L:$L,"Guia para download")+COUNTIFS('Mapa de Serviços'!$B:$B,$A8,'Mapa de Serviços'!$J:$J,"Calculadora")+COUNTIFS('Mapa de Marcas'!$D:$D,$A8,'Mapa de Marcas'!$L:$L,"Calculadora")+COUNTIFS('Mapa de Serviços'!$B:$B,$A8,'Mapa de Serviços'!$J:$J,"Página pilar de conteúdo")+COUNTIFS('Mapa de Marcas'!$D:$D,$A8,'Mapa de Marcas'!$L:$L,"Página pilar de conteúdo") -> 10 | J8: =COUNTIF('Mapa de Marcas'!$D:$D,$A8) -> 6 | K8: =COUNTIFS('Mapa de Serviços'!$B:$B,$A8,'Mapa de Serviços'!$P:$P,"Alta")+COUNTIFS('Mapa de Marcas'!$D:$D,$A8,'Mapa de Marcas'!$Q:$Q,"Alta") -> 14 | L8: =COUNTIFS('Mapa de Serviços'!$B:$B,$A8,'Mapa de Serviços'!$Q:$Q,"Lacuna")+COUNTIFS('Mapa de Marcas'!$D:$D,$A8,'Mapa de Marcas'!$R:$R,"Lacuna") -> 6 | M8: =COUNTIFS('Mapa de Serviços'!$B:$B,$A8,'Mapa de Serviços'!$S:$S,"Aprovar")+COUNTIFS('Mapa de Marcas'!$D:$D,$A8,'Mapa de Marcas'!$T:$T,"Aprovar") -> 0
